Not Found: /favicon.ico
"GET /favicon.ico HTTP/1.1" 404 15075
Not Found: /favicon.ico
"GET /favicon.ico HTTP/1.1" 404 15075
Not Found: /favicon.ico
"GET /favicon.ico HTTP/1.1" 404 15075
Internal Server Error: /otchet/
Traceback (most recent call last):
  File "D:\甑저奸niokr\venv\Lib\site-packages\django\core\handlers\exception.py", line 55, in inner
    response = get_response(request)
               ^^^^^^^^^^^^^^^^^^^^^
  File "D:\甑저奸niokr\venv\Lib\site-packages\django\core\handlers\base.py", line 197, in _get_response
    response = wrapped_callback(request, *callback_args, **callback_kwargs)
               ^^^^^^^^^^^^^^^^^^^^^^^^^^^^^^^^^^^^^^^^^^^^^^^^^^^^^^^^^^^^
  File "D:\甑저奸niokr\venv\Lib\site-packages\django\views\generic\base.py", line 104, in view
    return self.dispatch(request, *args, **kwargs)
           ^^^^^^^^^^^^^^^^^^^^^^^^^^^^^^^^^^^^^^^
  File "D:\甑저奸niokr\venv\Lib\site-packages\django\views\generic\base.py", line 143, in dispatch
    return handler(request, *args, **kwargs)
           ^^^^^^^^^^^^^^^^^^^^^^^^^^^^^^^^^
  File "D:\甑저奸niokr\gos_map\views\views.py", line 392, in post
    type_monographs=request.POST.grt('type_monographs_select')
                    ^^^^^^^^^^^^^^^^
AttributeError: 'QueryDict' object has no attribute 'grt'. Did you mean: 'get'?
"POST /otchet/ HTTP/1.1" 500 85036
Not Found: /favicon.ico
"GET /favicon.ico HTTP/1.1" 404 15075
Internal Server Error: /otchet/
Traceback (most recent call last):
  File "D:\甑저奸niokr\venv\Lib\site-packages\django\core\handlers\exception.py", line 55, in inner
    response = get_response(request)
               ^^^^^^^^^^^^^^^^^^^^^
  File "D:\甑저奸niokr\venv\Lib\site-packages\django\core\handlers\base.py", line 197, in _get_response
    response = wrapped_callback(request, *callback_args, **callback_kwargs)
               ^^^^^^^^^^^^^^^^^^^^^^^^^^^^^^^^^^^^^^^^^^^^^^^^^^^^^^^^^^^^
  File "D:\甑저奸niokr\venv\Lib\site-packages\django\views\generic\base.py", line 104, in view
    return self.dispatch(request, *args, **kwargs)
           ^^^^^^^^^^^^^^^^^^^^^^^^^^^^^^^^^^^^^^^
  File "D:\甑저奸niokr\venv\Lib\site-packages\django\views\generic\base.py", line 143, in dispatch
    return handler(request, *args, **kwargs)
           ^^^^^^^^^^^^^^^^^^^^^^^^^^^^^^^^^
  File "D:\甑저奸niokr\gos_map\views\views.py", line 392, in post
    type_monographs=request.POST.g社('type_monographs_select')
                    ^^^^^^^^^^^^^^^
AttributeError: 'QueryDict' object has no attribute 'gt'
"POST /otchet/ HTTP/1.1" 500 85032
Not Found: /favicon.ico
"GET /favicon.ico HTTP/1.1" 404 15075
Not Found: /favicon.ico
"GET /favicon.ico HTTP/1.1" 404 15075
Not Found: /favicon.ico
"GET /favicon.ico HTTP/1.1" 404 15075
Not Found: /favicon.ico
"GET /favicon.ico HTTP/1.1" 404 15075
Internal Server Error: /otchet/
Traceback (most recent call last):
  File "D:\甑저奸niokr\venv\Lib\site-packages\django\db\models\fields\__init__.py", line 2117, in get_prep_value
    return int(value)
           ^^^^^^^^^^
ValueError: invalid literal for int() with base 10: ''

The above exception was the direct cause of the following exception:

Traceback (most recent call last):
  File "D:\甑저奸niokr\venv\Lib\site-packages\django\core\handlers\exception.py", line 55, in inner
    response = get_response(request)
               ^^^^^^^^^^^^^^^^^^^^^
  File "D:\甑저奸niokr\venv\Lib\site-packages\django\core\handlers\base.py", line 197, in _get_response
    response = wrapped_callback(request, *callback_args, **callback_kwargs)
               ^^^^^^^^^^^^^^^^^^^^^^^^^^^^^^^^^^^^^^^^^^^^^^^^^^^^^^^^^^^^
  File "D:\甑저奸niokr\venv\Lib\site-packages\django\views\generic\base.py", line 104, in view
    return self.dispatch(request, *args, **kwargs)
           ^^^^^^^^^^^^^^^^^^^^^^^^^^^^^^^^^^^^^^^
  File "D:\甑저奸niokr\venv\Lib\site-packages\django\views\generic\base.py", line 143, in dispatch
    return handler(request, *args, **kwargs)
           ^^^^^^^^^^^^^^^^^^^^^^^^^^^^^^^^^
  File "D:\甑저奸niokr\gos_map\views\views.py", line 534, in post
    grants=grants.filter(type_grant=type_grant)
           ^^^^^^^^^^^^^^^^^^^^^^^^^^^^^^^^^^^^
  File "D:\甑저奸niokr\venv\Lib\site-packages\django\db\models\query.py", line 1476, in filter
    return self._filter_or_exclude(False, args, kwargs)
           ^^^^^^^^^^^^^^^^^^^^^^^^^^^^^^^^^^^^^^^^^^^^
  File "D:\甑저奸niokr\venv\Lib\site-packages\django\db\models\query.py", line 1494, in _filter_or_exclude
    clone._filter_or_exclude_inplace(negate, args, kwargs)
  File "D:\甑저奸niokr\venv\Lib\site-packages\django\db\models\query.py", line 1501, in _filter_or_exclude_inplace
    self._query.add_q(Q(*args, **kwargs))
  File "D:\甑저奸niokr\venv\Lib\site-packages\django\db\models\sql\query.py", line 1613, in add_q
    clause, _ = self._add_q(q_object, self.used_aliases)
                ^^^^^^^^^^^^^^^^^^^^^^^^^^^^^^^^^^^^^^^^
  File "D:\甑저奸niokr\venv\Lib\site-packages\django\db\models\sql\query.py", line 1645, in _add_q
    child_clause, needed_inner = self.build_filter(
                                 ^^^^^^^^^^^^^^^^^^
  File "D:\甑저奸niokr\venv\Lib\site-packages\django\db\models\sql\query.py", line 1559, in build_filter
    condition = self.build_lookup(lookups, col, value)
                ^^^^^^^^^^^^^^^^^^^^^^^^^^^^^^^^^^^^^^
  File "D:\甑저奸niokr\venv\Lib\site-packages\django\db\models\sql\query.py", line 1389, in build_lookup
    lookup = lookup_class(lhs, rhs)
             ^^^^^^^^^^^^^^^^^^^^^^
  File "D:\甑저奸niokr\venv\Lib\site-packages\django\db\models\lookups.py", line 30, in __init__
    self.rhs = self.get_prep_lookup()
               ^^^^^^^^^^^^^^^^^^^^^^
  File "D:\甑저奸niokr\venv\Lib\site-packages\django\db\models\fields\related_lookups.py", line 156, in get_prep_lookup
    self.rhs = target_field.get_prep_value(self.rhs)
               ^^^^^^^^^^^^^^^^^^^^^^^^^^^^^^^^^^^^^
  File "D:\甑저奸niokr\venv\Lib\site-packages\django\db\models\fields\__init__.py", line 2119, in get_prep_value
    raise e.__class__(
ValueError: Field 'id' expected a number but got ''.
"POST /otchet/ HTTP/1.1" 500 142431
Not Found: /favicon.ico
"GET /favicon.ico HTTP/1.1" 404 15075
Internal Server Error: /otchet/
Traceback (most recent call last):
  File "D:\甑저奸niokr\venv\Lib\site-packages\django\db\models\fields\__init__.py", line 2117, in get_prep_value
    return int(value)
           ^^^^^^^^^^
ValueError: invalid literal for int() with base 10: ''

The above exception was the direct cause of the following exception:

Traceback (most recent call last):
  File "D:\甑저奸niokr\venv\Lib\site-packages\django\core\handlers\exception.py", line 55, in inner
    response = get_response(request)
               ^^^^^^^^^^^^^^^^^^^^^
  File "D:\甑저奸niokr\venv\Lib\site-packages\django\core\handlers\base.py", line 197, in _get_response
    response = wrapped_callback(request, *callback_args, **callback_kwargs)
               ^^^^^^^^^^^^^^^^^^^^^^^^^^^^^^^^^^^^^^^^^^^^^^^^^^^^^^^^^^^^
  File "D:\甑저奸niokr\venv\Lib\site-packages\django\views\generic\base.py", line 104, in view
    return self.dispatch(request, *args, **kwargs)
           ^^^^^^^^^^^^^^^^^^^^^^^^^^^^^^^^^^^^^^^
  File "D:\甑저奸niokr\venv\Lib\site-packages\django\views\generic\base.py", line 143, in dispatch
    return handler(request, *args, **kwargs)
           ^^^^^^^^^^^^^^^^^^^^^^^^^^^^^^^^^
  File "D:\甑저奸niokr\gos_map\views\views.py", line 504, in post
    monographss=monographss.filter(type_monographs=TypeMonographs.objects.get(pk=type_monographs))
                                                   ^^^^^^^^^^^^^^^^^^^^^^^^^^^^^^^^^^^^^^^^^^^^^^
  File "D:\甑저奸niokr\venv\Lib\site-packages\django\db\models\manager.py", line 87, in manager_method
    return getattr(self.get_queryset(), name)(*args, **kwargs)
           ^^^^^^^^^^^^^^^^^^^^^^^^^^^^^^^^^^^^^^^^^^^^^^^^^^^
  File "D:\甑저奸niokr\venv\Lib\site-packages\django\db\models\query.py", line 635, in get
    clone = self._chain() if self.query.combinator else self.filter(*args, **kwargs)
                                                        ^^^^^^^^^^^^^^^^^^^^^^^^^^^^
  File "D:\甑저奸niokr\venv\Lib\site-packages\django\db\models\query.py", line 1476, in filter
    return self._filter_or_exclude(False, args, kwargs)
           ^^^^^^^^^^^^^^^^^^^^^^^^^^^^^^^^^^^^^^^^^^^^
  File "D:\甑저奸niokr\venv\Lib\site-packages\django\db\models\query.py", line 1494, in _filter_or_exclude
    clone._filter_or_exclude_inplace(negate, args, kwargs)
  File "D:\甑저奸niokr\venv\Lib\site-packages\django\db\models\query.py", line 1501, in _filter_or_exclude_inplace
    self._query.add_q(Q(*args, **kwargs))
  File "D:\甑저奸niokr\venv\Lib\site-packages\django\db\models\sql\query.py", line 1613, in add_q
    clause, _ = self._add_q(q_object, self.used_aliases)
                ^^^^^^^^^^^^^^^^^^^^^^^^^^^^^^^^^^^^^^^^
  File "D:\甑저奸niokr\venv\Lib\site-packages\django\db\models\sql\query.py", line 1645, in _add_q
    child_clause, needed_inner = self.build_filter(
                                 ^^^^^^^^^^^^^^^^^^
  File "D:\甑저奸niokr\venv\Lib\site-packages\django\db\models\sql\query.py", line 1559, in build_filter
    condition = self.build_lookup(lookups, col, value)
                ^^^^^^^^^^^^^^^^^^^^^^^^^^^^^^^^^^^^^^
  File "D:\甑저奸niokr\venv\Lib\site-packages\django\db\models\sql\query.py", line 1389, in build_lookup
    lookup = lookup_class(lhs, rhs)
             ^^^^^^^^^^^^^^^^^^^^^^
  File "D:\甑저奸niokr\venv\Lib\site-packages\django\db\models\lookups.py", line 30, in __init__
    self.rhs = self.get_prep_lookup()
               ^^^^^^^^^^^^^^^^^^^^^^
  File "D:\甑저奸niokr\venv\Lib\site-packages\django\db\models\lookups.py", line 364, in get_prep_lookup
    return super().get_prep_lookup()
           ^^^^^^^^^^^^^^^^^^^^^^^^^
  File "D:\甑저奸niokr\venv\Lib\site-packages\django\db\models\lookups.py", line 88, in get_prep_lookup
    return self.lhs.output_field.get_prep_value(self.rhs)
           ^^^^^^^^^^^^^^^^^^^^^^^^^^^^^^^^^^^^^^^^^^^^^^
  File "D:\甑저奸niokr\venv\Lib\site-packages\django\db\models\fields\__init__.py", line 2119, in get_prep_value
    raise e.__class__(
ValueError: Field 'id' expected a number but got ''.
"POST /otchet/ HTTP/1.1" 500 155799
Not Found: /favicon.ico
"GET /favicon.ico HTTP/1.1" 404 15075
Not Found: /favicon.ico
"GET /favicon.ico HTTP/1.1" 404 15075
Not Found: /favicon.ico
"GET /favicon.ico HTTP/1.1" 404 15075
Not Found: /favicon.ico
"GET /favicon.ico HTTP/1.1" 404 15075
Not Found: /favicon.ico
"GET /favicon.ico HTTP/1.1" 404 15075
Not Found: /favicon.ico
"GET /favicon.ico HTTP/1.1" 404 15075
Not Found: /favicon.ico
"GET /favicon.ico HTTP/1.1" 404 15075
Not Found: /favicon.ico
"GET /favicon.ico HTTP/1.1" 404 15075
Not Found: /favicon.ico
"GET /favicon.ico HTTP/1.1" 404 15075
Not Found: /favicon.ico
"GET /favicon.ico HTTP/1.1" 404 15075
Not Found: /favicon.ico
"GET /favicon.ico HTTP/1.1" 404 15075
Not Found: /favicon.ico
"GET /favicon.ico HTTP/1.1" 404 15075
Not Found: /favicon.ico
"GET /favicon.ico HTTP/1.1" 404 15075
Not Found: /favicon.ico
"GET /favicon.ico HTTP/1.1" 404 15075
